<?xml version="1.0"?>
<robot xmlns:xacro="http://ros.org/wiki/xacro">

  <xacro:macro name="simple_wheel" params="parent suffix xyz rpy">
    
    <!-- Link definition -->
    <link name="simple_wheel_link_${suffix}">
      <visual>
        <origin xyz="0 0 0" rpy="0 0 0"/>
        <geometry>
          <cylinder length="0.018" radius="0.033"/>
        </geometry>
        <material name="dark"/>
      </visual>

      <collision>
        <origin xyz="0 0 0" rpy="0 0 0"/>
        <geometry>
          <cylinder length="0.018" radius="0.033"/>
        </geometry>
      </collision>

      <inertial>
        <origin xyz="0 0 0"/>
        <mass value="0.02849894"/> <!-- 28.5g -->
        <inertia 
          ixx="1.1175580e-05" ixy="-4.2369783e-11" ixz="-5.9381719e-09"
          iyy="1.1192413e-05" iyz="-1.4400107e-11"
          izz="2.0712558e-05"/>
      </inertial>
    </link>

    <!-- Joint connecting it to the parent -->
    <joint name="simple_wheel_joint_${suffix}" type="continuous">
      <parent link="${parent}"/>
      <child link="simple_wheel_link_${suffix}"/>
      <origin xyz="${xyz}" rpy="${rpy}"/>
      <axis xyz="0 0 1"/>
    </joint>

  </xacro:macro>
</robot>

